<?xml version="1.0" encoding="utf-8"?>
<!-- =================================================================================== -->
<!-- |    This document was autogenerated by xacro from /home/dan/catkin_ws/src/tondeuse/urdf/tondeuse1.2.xacro | -->
<!-- |    EDITING THIS FILE BY HAND IS NOT RECOMMENDED                                 | -->
<!-- =================================================================================== -->
<robot name="tondeuse1.2">
  <static>false</static>
  <material name="black">
    <color rgba="0.0 0.0 0.0 1.0"/>
  </material>
  <material name="blue">
    <color rgba="0.203125 0.23828125 0.28515625 1.0"/>
  </material>
  <material name="green">
    <color rgba="0.0 0.8 0.0 1.0"/>
  </material>
  <material name="grey">
    <color rgba="0.2 0.2 0.2 1.0"/>
  </material>
  <material name="orange">
    <color rgba="1.0 0.423529411765 0.0392156862745 1.0"/>
  </material>
  <material name="brown">
    <color rgba="0.870588235294 0.811764705882 0.764705882353 1.0"/>
  </material>
  <material name="red">
    <color rgba="0.80078125 0.12890625 0.1328125 1.0"/>
  </material>
  <material name="white">
    <color rgba="1.0 1.0 1.0 1.0"/>
  </material>
  <gazebo reference="base_link">
    <material>red</material>
  </gazebo>
  <!-- base_link -->
  <link name="base_link">
    <!-- pose and inertial >  
    <inertial>
      <mass value="10"/>
      <origin rpy="0 0 0" xyz="0 0.152 0.01"/>
      <inertia ixx="0.0395416666667" ixy="0" ixz="0" iyy="0.106208333333" iyz="0" izz="0.106208333333"/>
    </inertial-->
    <!-- body -->
    <collision name="collision_chassis">
      <origin rpy="0 0 0" xyz="0 0.152 0.01"/>
      <geometry>
        <mesh filename="file:///home/dan/catkin_ws/src/tondeuse/urdf/mesh/frame.dae" scale="0.001 0.001 0.001"/>
      </geometry>
    </collision>
    <visual>
      <origin rpy="0 0 0" xyz="0 0.152 0.01"/>
      <geometry>
        <mesh filename="file:///home/dan/catkin_ws/src/tondeuse/urdf/mesh/frame.dae" scale="0.001 0.001 0.001"/>
      </geometry>
    </visual>
  </link>
  <gazebo reference="caster_left_link">
    <material>orange</material>
  </gazebo>
  <gazebo reference="caster_right_link">
    <material>orange</material>
  </gazebo>
  <!-- caster right -->
  <link name="caster_right_link">
    <collision name="caster_right_collision">
      <origin rpy="0 1.570796 0" xyz="0 0 0"/>
      <geometry>
        <cylinder length="0.02" radius="0.02"/>
      </geometry>
      <surface>
        <friction>
          <ode>
            <mu>0</mu>
            <mu2>0</mu2>
            <slip1>0.1</slip1>
            <slip2>0.1</slip2>
          </ode>
        </friction>
      </surface>
    </collision>
    <visual name="caster_right_visual">
      <origin rpy="0 1.570796 0" xyz="0 0 0"/>
      <geometry>
        <mesh filename="file:///home/dan/catkin_ws/src/tondeuse/urdf/mesh/roulette.dae" scale="0.001 0.001 0.001"/>
      </geometry>
    </visual>
    <inertial>
      <mass value="0.01"/>
      <inertia ixx="0.01" ixy="0.0" ixz="0.0" iyy="0.01" iyz="0.0" izz="0.01"/>
    </inertial>
  </link>
  <joint name="caster_right_joint" type="fixed">
    <origin rpy="0 0 0" xyz="0.095 0.334 0.02"/>
    <child link="caster_right_link"/>
    <parent link="base_link"/>
    <axis xyz="1 0 0 "/>
    <limit effort="10000" velocity="1000"/>
    <joint_properties damping="1.0" friction="1.0"/>
  </joint>
  <!-- caster left -->
  <link name="caster_left_link">
    <collision name="caster_left_collision">
      <origin rpy="0 1.570796 0" xyz="0 0 0"/>
      <geometry>
        <cylinder length="0.02" radius="0.02"/>
      </geometry>
      <surface>
        <friction>
          <ode>
            <mu>0</mu>
            <mu2>0</mu2>
            <slip1>0.1</slip1>
            <slip2>0.1</slip2>
          </ode>
        </friction>
      </surface>
    </collision>
    <visual name="caster_left_visual">
      <origin rpy="0 1.570796 0" xyz="0 0 0"/>
      <geometry>
        <mesh filename="file:///home/dan/catkin_ws/src/tondeuse/urdf/mesh/roulette.dae" scale="0.001 0.001 0.001"/>
      </geometry>
    </visual>
    <inertial>
      <mass value="0.01"/>
      <inertia ixx="0.01" ixy="0.0" ixz="0.0" iyy="0.01" iyz="0.0" izz="0.01"/>
    </inertial>
  </link>
  <joint name="caster_left_joint" type="fixed">
    <origin rpy="0 0 0" xyz="-0.110 0.334 0.02"/>
    <child link="caster_left_link"/>
    <parent link="base_link"/>
    <axis xyz="1 0 0 "/>
    <limit effort="10000" velocity="1000"/>
    <joint_properties damping="1.0" friction="1.0"/>
  </joint>
  <!-- Wheels materials color-->
  <gazebo reference="wheel_left_link">
    <material>green</material>
  </gazebo>
  <gazebo reference="wheel_right_link">
    <material>green</material>
  </gazebo>
  <!-- Wheels diff driver-->
  <gazebo>
    <plugin filename="libgazebo_ros_diff_drive.so" name="differential_drive_controller">
      <alwaysOn>true</alwaysOn>
      <updateRate>20</updateRate>
      <leftJoint>left_wheel_joint</leftJoint>
      <rightJoint>right_wheel_joint</rightJoint>
      <wheelSeparation>0.45</wheelSeparation>
      <wheelDiameter>0.217</wheelDiameter>
      <torque>50</torque>
      <commandTopic>cmd_vel</commandTopic>
      <odometryTopic>odom</odometryTopic>
      <odometryFrame>odom</odometryFrame>
      <robotBaseFrame>link_chassis</robotBaseFrame>
      <publishWheelTF>true</publishWheelTF>
      <publishTf>1</publishTf>
      <publishWheelJointState>true</publishWheelJointState>
      <broadcastTF>1</broadcastTF>
    </plugin>
  </gazebo>
  <!-- wheel_left_link -->
  <link name="wheel_left_link">
    <inertial>
      <mass value="0.2"/>
      <origin rpy="0 1.5707 0" xyz="0 0 0"/>
      <inertia ixx="0.000526666666667" ixy="0" ixz="0" iyy="0.000526666666667" iyz="0" izz="0.001"/>
    </inertial>
    <collision name="wheel_left_collision">
      <origin rpy="0 1.5707 0" xyz="0 0 0"/>
      <geometry>
        <mesh filename="file:///home/dan/catkin_ws/src/tondeuse/urdf/mesh/roue.dae" scale="0.001 0.001 0.001"/>
      </geometry>
    </collision>
    <visual name="wheel_left_visual">
      <origin rpy="0 1.5707 0" xyz="0 0 0"/>
      <geometry>
        <mesh filename="file:///home/dan/catkin_ws/src/tondeuse/urdf/mesh/roue.dae" scale="0.001 0.001 0.001"/>
      </geometry>
    </visual>
  </link>
  <joint name="wheel_left_joint" type="continuous">
    <origin rpy="0 0 3.1415" xyz="-0.19 0 0.109"/>
    <child link="wheel_left_link"/>
    <parent link="base_link"/>
    <axis xyz="1 0 0"/>
    <limit effort="10000" velocity="1000"/>
    <joint_properties damping="1.0" friction="1.0"/>
  </joint>
  <!-- wheel_right_link -->
  <link name="wheel_right_link">
    <inertial>
      <mass value="0.2"/>
      <origin rpy="0 -1.57 0" xyz="0 0 0"/>
      <inertia ixx="0.000526666666667" ixy="0" ixz="0" iyy="0.000526666666667" iyz="0" izz="0.001"/>
    </inertial>
    <collision name="wheel_right_collision">
      <origin rpy="0 -1.57 0" xyz="0 0 0"/>
      <geometry>
        <mesh filename="file:///home/dan/catkin_ws/src/tondeuse/urdf/mesh/roue.dae" scale="0.001 0.001 0.001"/>
      </geometry>
    </collision>
    <visual name="wheel_right_visual">
      <origin rpy="0 -1.57 0" xyz="0 0 0"/>
      <geometry>
        <mesh filename="file:///home/dan/catkin_ws/src/tondeuse/urdf/mesh/roue.dae" scale="0.001 0.001 0.001"/>
      </geometry>
    </visual>
  </link>
  <joint name="wheel_right_joint" type="continuous">
    <origin rpy="0 0 3.1415" xyz="0.19 0 0.109"/>
    <child link="wheel_right_link"/>
    <parent link="base_link"/>
    <axis xyz="1 0 0 "/>
    <limit effort="10000" velocity="1000"/>
    <joint_properties damping="1.0" friction="1.0"/>
  </joint>
  <!-- lidar_link-->
  <link name="lidar_link">
    <inertial>
      <origin rpy="0 0 0" xyz="-0.01 -0.065 -0.06"/>
      <geometry>
        <mesh filename="file:///home/dan/catkin_ws/src/tondeuse/urdf/mesh/lidar.stl" scale="0.001 0.001 0.001"/>
      </geometry>
      <mass value="1"/>
      <inertia ixx="0.00145833333333" ixy="0" ixz="0" iyy="0.00145833333333" iyz="0" izz="0.00125"/>
    </inertial>
    <visual>
      <origin rpy="0 0 -1.57" xyz="-0.01 -0.065 -0.06"/>
      <geometry>
        <mesh filename="file:///home/dan/catkin_ws/src/tondeuse/urdf/mesh/lidar.stl" scale="0.001 0.001 0.001"/>
      </geometry>
      <material name="orange"/>
    </visual>
    <collision>
      <origin rpy="0 0 -1.57" xyz="-0.01 -0.065 -0.06"/>
      <geometry>
        <mesh filename="file:///home/dan/catkin_ws/src/tondeuse/urdf/mesh/lidar.stl" scale="0.001 0.001 0.001"/>
      </geometry>
    </collision>
  </link>
  <joint name="lidar_link_joint" type="fixed">
    <origin rpy="0 0 0 " xyz="-0.185 0.1 0.3"/>
    <parent link="base_link"/>
    <child link="lidar_link"/>
    <axis xyz="0 0 1"/>
  </joint>
  <gazebo reference="lidar_link">
    <material>orange</material>
  </gazebo>
  <!-- RpLidar A2 using GPU -->
  <gazebo reference="laser">
    <sensor name="head_rplidar_sensor" type="gpu_ray">
      <pose>-0.185 0.1 0.3 0 0 0</pose>
      <visualize>false</visualize>
      <update_rate>40</update_rate>
      <ray>
        <scan>
          <horizontal>
            <samples>720</samples>
            <resolution>1</resolution>
            <min_angle>-3.14159265</min_angle>
            <max_angle>3.14159265</max_angle>
          </horizontal>
        </scan>
        <range>
          <min>0.2</min>
          <max>12.0</max>
          <resolution>0.01</resolution>
        </range>
        <noise>
          <type>gaussian</type>
          <mean>0.0</mean>
          <stddev>0.01</stddev>
        </noise>
      </ray>
      <plugin filename="libgazebo_ros_gpu_laser.so" name="gazebo_ros_head_rplidar_controller">
        <topicName>scan</topicName>
        <frameName>laser</frameName>
      </plugin>
    </sensor>
  </gazebo>
  &gt;



  <!-- imu_link -->
  <link name="imu_link">
    <visual name="caster_right_visual">
      <origin rpy="0 1.570796 0" xyz="0 0 0"/>
      <geometry>
        <box size="0.01 0.025 0.003"/>
      </geometry>
    </visual>
  </link>
  <joint name="imu_link_joint" type="fixed">
    <origin rpy="0 0 0" xyz="0 0.6 0.12"/>
    <child link="imu_link"/>
    <parent link="base_link"/>
    <axis xyz="1 0 0 "/>
    <limit effort="10000" velocity="1000"/>
    <joint_properties damping="1.0" friction="1.0"/>
  </joint>
  <gazebo reference="base_link">
    <material>red</material>
  </gazebo>
  <gazebo reference="imu_link">
    <gravity>true</gravity>
    <sensor name="imu_sensor" type="imu">
      <always_on>true</always_on>
      <update_rate>100</update_rate>
      <visualize>true</visualize>
      <topic>__default_topic__</topic>
      <plugin filename="libgazebo_ros_imu_sensor.so" name="imu_plugin">
        <topicName>imu</topicName>
        <bodyName>imu_link</bodyName>
        <updateRateHZ>10.0</updateRateHZ>
        <gaussianNoise>0.0</gaussianNoise>
        <xyzOffset>0 0 0</xyzOffset>
        <rpyOffset>0 0 0</rpyOffset>
        <frameName>imu_link</frameName>
        <initialOrientationAsReference>false</initialOrientationAsReference>
      </plugin>
      <pose>0 0 0 0 0 0</pose>
    </sensor>
  </gazebo>
</robot>

