<?xml version="1.0"?>
<robot xmlns:xacro="http://www.ros.org/wiki/xacro">  

<!-- wheel_left_link --> 
<link name="wheel_left_link">
    <inertial>
      <mass value="0.2"/>
      <origin rpy="0 1.5707 0" xyz="0 0 0" />
      <inertia ixx="0.000526666666667" ixy="0" ixz="0" iyy="0.000526666666667" iyz="0" izz="0.001"/>
    </inertial>
    <collision name="wheel_left_collision">
      <origin rpy="0 1.5707 0" xyz="0 0 0" />
      <geometry>
        <mesh filename="file://$(find tondeuse)/urdf/mesh/roue.dae" scale="0.001 0.001 0.001"/>
      </geometry>
    </collision>
    <visual name="wheel_left_visual">
      <origin rpy="0 1.5707 0" xyz="0 0 0" />
      <geometry>
          <mesh filename="file://$(find tondeuse)/urdf/mesh/roue.dae" scale="0.001 0.001 0.001"/>
      </geometry>
    </visual>
</link>

<joint name="wheel_left_joint" type="continuous">
    <origin rpy="0 0 3.1415" xyz="-0.19 0 0.109" />
    <child link="wheel_left_link"/>
    <parent link="base_link"/>
    <axis xyz="1 0 0"/>
    <limit effort="10000" velocity="1000"/>
    <joint_properties damping="1.0" friction="1.0"/>
</joint>

  <!-- wheel_right_link -->
<link name="wheel_right_link">
    <inertial>
      <mass value="0.2"/>
      <origin rpy="0 -1.57 0" xyz="0 0 0"/>
      <inertia ixx="0.000526666666667" ixy="0" ixz="0" iyy="0.000526666666667" iyz="0" izz="0.001"/>
    </inertial>
    <collision name="wheel_right_collision">
      <origin rpy="0 -1.57 0" xyz="0 0 0" />
      <geometry>
        <mesh filename="file://$(find tondeuse)/urdf/mesh/roue.dae" scale="0.001 0.001 0.001"/>
      </geometry>
    </collision>
    <visual name="wheel_right_visual">
      <origin rpy="0 -1.57 0" xyz="0 0 0"/>
      <geometry>
        <mesh filename="file://$(find tondeuse)/urdf/mesh/roue.dae" scale="0.001 0.001 0.001"/>
      </geometry>
    </visual>
</link>
<joint name="wheel_right_joint" type="continuous">
    <origin rpy="0 0 3.1415" xyz="0.19 0 0.109" />
    <child link="wheel_right_link"/>
    <parent link="base_link"/>
    <axis xyz="1 0 0 "/>
    <limit effort="10000" velocity="1000"/>
    <joint_properties damping="1.0" friction="1.0"/>
</joint>

  </robot>